<?xml version="1.0" ?>
<!-- =================================================================================== -->
<!-- |    This document was autogenerated by xacro from turtle.urdf.xacro              | -->
<!-- |    EDITING THIS FILE BY HAND IS NOT RECOMMENDED                                 | -->
<!-- =================================================================================== -->
<robot name="turtlebot">
  <material name="black_color">
    <color rgba="0.0 0.0 0.0 1.0"/>
  </material>
  <material name="blue_color">
    <color rgba="0.0 0.0 1.0 1.0"/>
  </material>
  <material name="green_color">
    <color rgba="0.0 1.0 0.0 1.0"/>
  </material>
  <material name="red_color">
    <color rgba="1.0 0.0 0.0 1.0"/>
  </material>
  <material name="white_color">
    <color rgba="1.0 1.0 1.0 1.0"/>
  </material>
  <link name="base_link">
    <visual>
      <geometry>
        <box size="0.3 0.25 0.125"/>
      </geometry>
      <origin rpy="0 0 0" xyz="0 0 0"/>
      <material name="red_color"/>
    </visual>
    <collision>
      <geometry>
        <box size="0.3 0.25 0.125"/>
      </geometry>
      <origin rpy="0 0 0" xyz="0 0 0"/>
    </collision>
    <inertial>
      <mass value="0.1"/>
      <origin xyz="0 0 0"/>
      <inertia ixx="0.0001" ixy="0.0" ixz="0.0" iyy="0.0001" iyz="0.0" izz="0.0001"/>
    </inertial>
  </link>
  <link name="right_wheel_link">
    <visual>
      <origin rpy="1.5708 0 0" xyz="0 0 0"/>
      <geometry>
        <cylinder length="0.025" radius="0.085"/>
      </geometry>
      <material name="blue_color"/>
    </visual>
    <inertial>
      <mass value="0.1"/>
      <origin xyz="0 0 0"/>
      <inertia ixx="0.0001" ixy="0.0" ixz="0.0" iyy="0.0001" iyz="0.0" izz="0.0001"/>
    </inertial>
  </link>
  <joint name="right_wheel_joint" type="continuous">
    <parent link="base_link"/>
    <child link="right_wheel_link"/>
    <origin rpy="0 0 0" xyz="0 -0.15 0"/>
    <axis xyz="0 1 0"/>
  </joint>
  <gazebo reference="right_wheel_link">
    <mu1 value="1.0"/>
    <mu2 value="1.0"/>
  </gazebo>
  <link name="left_wheel_link">
    <visual>
      <origin rpy="1.5708 0 0" xyz="0 0 0"/>
      <geometry>
        <cylinder length="0.025" radius="0.085"/>
      </geometry>
      <material name="blue_color"/>
    </visual>
    <inertial>
      <mass value="0.1"/>
      <origin xyz="0 0 0"/>
      <inertia ixx="0.0001" ixy="0.0" ixz="0.0" iyy="0.0001" iyz="0.0" izz="0.0001"/>
    </inertial>
  </link>
  <joint name="left_wheel_joint" type="continuous">
    <parent link="base_link"/>
    <child link="left_wheel_link"/>
    <origin rpy="0 0 0" xyz="0 0.15 0"/>
    <axis xyz="0 1 0"/>
  </joint>
  <gazebo reference="left_wheel_link">
    <mu1 value="1.0"/>
    <mu2 value="1.0"/>
  </gazebo>
  <link name="laser_link">
    <visual>
      <origin rpy="0 0 0" xyz="0 0 0"/>
      <geometry>
        <box size="0.05 0.05 0.02"/>
      </geometry>
      <material name="laser_material">
        <color rgba="1 0 0 1"/>
      </material>
    </visual>
    <inertial>
      <mass value="0.1"/>
      <origin xyz="0 0 0"/>
      <inertia ixx="0.0001" ixy="0.0" ixz="0.0" iyy="0.0001" iyz="0.0" izz="0.0001"/>
    </inertial>
  </link>
  <joint name="laser_joint" type="fixed">
    <parent link="base_link"/>
    <child link="laser_link"/>
    <origin rpy="0 0 0" xyz="0.15 0 0.08"/>
  </joint>
  <gazebo reference="laser_link">
    <sensor name="laser_sensor" type="gpu_lidar">
      <update_rate>10</update_rate>
      <ray>...</ray>
      <always_on>true</always_on>
      <plugin filename="libignition-gazebo-sensors-system.so" name="ignition::gazebo::systems::Sensors">
        <topic>/scan</topic>
        <frame_name>laser_link</frame_name>
      </plugin>
    </sensor>
  </gazebo>
  <gz>
    <plugin filename="gz-sim-diff-drive-system" name="gz::sim::systems::DiffDrive">
      <left_wheel>left_wheel_joint</left_wheel>
      <right_wheel>right_wheel_joint</right_wheel>
      <wheel_separation>0.3</wheel_separation>
      <wheel_radius>0.085</wheel_radius>
      <command_topic>cmd_vel</command_topic>
      <odom_topic>odom</odom_topic>
      <update_rate>50</update_rate>
    </plugin>
  </gz>
  <gz>
    <plugin filename="libgazebo_ros_init.so" name="gazebo_ros_init"/>
    <plugin filename="libgazebo_ros_factory.so" name="gazebo_ros_factory"/>
  </gz>
</robot>
