<?xml version="1.0" ?>
<sdf version="1.8">
  <model name="turtlebot">
    <link name="base_link">
      <pose>0 0 0.125 0 0 0</pose>
      <inertial>
        <mass>0.1</mass>
        <inertia>
          <ixx>0.0001</ixx>
          <ixy>0</ixy>
          <ixz>0</ixz>
          <iyy>0.0001</iyy>
          <iyz>0</iyz>
          <izz>0.0001</izz>
        </inertia>
      </inertial>
      <visual name="base_link_visual">
        <geometry>
          <box>
            <size>0.3 0.25 0.125</size>
          </box>
        </geometry>
        <material>
          <ambient>1 0 0 1</ambient>
          <diffuse>1 0 0 1</diffuse>
        </material>
      </visual>
      <collision name="base_link_collision">
        <geometry>
          <box>
            <size>0.3 0.25 0.125</size>
          </box>
        </geometry>
      </collision>
    </link>

    <link name="right_wheel_link">
      <pose>0 -0.15 0.085 1.5708 0 0</pose>
      <inertial>
        <mass>0.1</mass>
        <inertia>
          <ixx>0.0001</ixx>
          <ixy>0</ixy>
          <ixz>0</ixz>
          <iyy>0.0001</iyy>
          <iyz>0</iyz>
          <izz>0.0001</izz>
        </inertia>
      </inertial>
      <visual name="right_wheel_visual">
        <geometry>
          <cylinder>
            <radius>0.085</radius>
            <length>0.025</length>
          </cylinder>
        </geometry>
        <material>
          <ambient>0 0 1 1</ambient>
          <diffuse>0 0 1 1</diffuse>
        </material>
      </visual>
      <collision name="right_wheel_collision">
        <geometry>
          <cylinder>
            <radius>0.085</radius>
            <length>0.025</length>
          </cylinder>
        </geometry>
      </collision>
    </link>

    <link name="left_wheel_link">
      <pose>0 0.15 0.085 1.5708 0 0</pose>
      <inertial>
        <mass>0.1</mass>
        <inertia>
          <ixx>0.0001</ixx>
          <ixy>0</ixy>
          <ixz>0</ixz>
          <iyy>0.0001</iyy>
          <iyz>0</iyz>
          <izz>0.0001</izz>
        </inertia>
      </inertial>
      <visual name="left_wheel_visual">
        <geometry>
          <cylinder>
            <radius>0.085</radius>
            <length>0.025</length>
          </cylinder>
        </geometry>
        <material>
          <ambient>0 0 1 1</ambient>
          <diffuse>0 0 1 1</diffuse>
        </material>
      </visual>
      <collision name="left_wheel_collision">
        <geometry>
          <cylinder>
            <radius>0.085</radius>
            <length>0.025</length>
          </cylinder>
        </geometry>
      </collision>
    </link>

    <link name="laser_link">
      <pose>0.15 0 0.205 0 0 0</pose>
      <inertial>
        <mass>0.1</mass>
        <inertia>
          <ixx>0.0001</ixx>
          <ixy>0</ixy>
          <ixz>0</ixz>
          <iyy>0.0001</iyy>
          <iyz>0</iyz>
          <izz>0.0001</izz>
        </inertia>
      </inertial>
      <visual name="laser_visual">
        <geometry>
          <box>
            <size>0.05 0.05 0.02</size>
          </box>
        </geometry>
        <material>
          <ambient>1 0 0 1</ambient>
          <diffuse>1 0 0 1</diffuse>
        </material>
      </visual>
      <sensor name="gpu_lidar" type="gpu_lidar">
        <lidar>
          <scan>
            <horizontal>
              <samples>1800</samples>
              <resolution>1</resolution>
              <min_angle>-3.1459</min_angle>
              <max_angle>3.1459</max_angle>
            </horizontal>
            <vertical>
              <samples>16</samples>
              <resolution>1</resolution>
              <min_angle>-0.261799</min_angle>
              <max_angle>0.261799</max_angle>
            </vertical>
          </scan>
          <range>
            <min>0.05</min>
            <max>100</max>
            <resolution>0.01</resolution>
          </range>
          <noise>
            <type>gaussian</type>
            <mean>0</mean>
            <stddev>0.01</stddev>
          </noise>
        </lidar>
        <gz_frame_id>saye/sensor_link</gz_frame_id>
        <topic>laser_scan</topic>
        <visualize>true</visualize>
        <update_rate>10</update_rate>
      </sensor>


    </link>

    <joint name="right_wheel_joint" type="revolute">
      <parent>base_link</parent>
      <child>right_wheel_link</child>
      <axis>
        <xyz>0 0 1</xyz> </axis>
    </joint>

    <joint name="left_wheel_joint" type="revolute">
      <parent>base_link</parent>
      <child>left_wheel_link</child>
      <axis>
        <xyz>0 0 1</xyz>
      </axis>
    </joint>

    <joint name="laser_joint" type="fixed">
      <parent>base_link</parent>
      <child>laser_link</child>
    </joint>

    <plugin filename="gz-sim-diff-drive-system" name="gz::sim::systems::DiffDrive">
      <left_wheel>left_wheel_joint</left_wheel>
      <right_wheel>right_wheel_joint</right_wheel>
      <wheel_separation>0.3</wheel_separation>
      <wheel_radius>0.085</wheel_radius>
      <topic>cmd_vel</topic>
      <odom_topic>odom</odom_topic>
      <frame_id>odom</frame_id>
      <child_frame_id>base_link</child_frame_id>
    </plugin>
  </model>
</sdf>